Workbook
Name Lista_Especie: 'LISTA-ESPECIES'!$A$4:$D$102
Name TESTE: 'IF-100%'!#REF!
Name TESTE_1: #REF!
Name TESTE_10: #REF!
Name TESTE_11: #REF!
Name TESTE_12: #REF!
Name TESTE_13: #REF!
Name TESTE_14: #REF!
Name TESTE_15: #REF!
Name TESTE_16: #REF!
Name TESTE_17: #REF!
Name TESTE_2: #REF!
Name TESTE_3: #REF!
Name TESTE_4: #REF!
Name TESTE_5: #REF!
Name TESTE_6: #REF!
Name TESTE_7: #REF!
Name TESTE_8: #REF!
Name TESTE_9: #REF!
Name TESTE2: #REF!
Name TESTE3: #REF!
Name TESTE4: #REF!
Name TESTE5: #REF!
Name UT_01: #REF!

Sheet ROTEIRO
A6: ROTEIRO PARA ANÁLISE TÉCNICA DE IF-100% PARA PMFS (Versão 2.0; Data: 10/12/2025)
A8: Autor: Prof. Deivison Venicio Souza
A9: Insituição de Origem: Universidade Federal do Pará
A10: Curso: Engenharia Florestal/UFRA/Forma Pará - Pacajá
A11: Disciplina: Inventário Florestal (EFBEL249)
A13: Legislação com diretrizes técnicas para análise de Censo Florestal (IF-100%) no âmbito do MFS de Florestas Nativas no Bioma Amazônia
A15: Decreto nº 5.975 de 30 de novembro 2006 (Defini fundamentos técnicos gerais do PMFS, transporte de produtos e subprodutos florestais)
A16: Norma de Execução/IBAMA 01 de 24 de 04 de 2007 (Diretrizes Técnicas para Elaboração dos PMFS)
A17: Resolução CONAMA nº 406 de 02 de fevereiro de 2009 (Parâmetros técnicos para elaboração, avaliação e execução de PMFS fins madeireiros)
A18: Portaria MMA nº 443 de 17 de dezembro de 2014 (Lista as espécies da flora brasileira ameaçadas de extinção)
A19: Portaria MMA nº 148 de 07 de junho de 2022 (Altera anexos da Portaria MMA nº 443, de 17 de dezembro de 2014)
A20: Instrução Normativa nº 01 de 12 de fevereiro de 2015 – MMA (Regulamenta o manejo das espécies vulneráveis - VU)
... A28: 👉 PASSO 1: Defina a lista de espécies que devem ser consideradas para exploração florestal (corte): (espécies de valor comercial no mercado)
A30: Nome Vulgar | B30: Nome Científico | D30: Aspectos Gerais:
A31: Angelim-Pedra | B31: Hymenolobium petraeum Ducke | D31: 1 - Tipologia Florestal: Floresta Ombrófila Densa
A32: Cedrarana | B32: Cedrelinga catenaeformis Ducke | D32: 2 - Ciclo de corte: 35 anos (com previsão de uso de máquinas para arraste de toras).
A33: Cumaru | B33: Dipteryx odorata (Aubl.) Willd. | D33: 3 - Intensidade máxima de corte: 30 m³/ha
A34: Cupiúba | B34: Goupia glabra Aubl. | D34: 4 - Estimativa de Produtividade Anual: 0,86 m³/ha/ano
A35: Freijó | B35: Cordia goeldiana Huber | D35: 5 - Diâmetro Mínimo de Corte (DMC): 50 cm (todas as espécies, exceto para aquelas com regulamentação específica)
A36: Garapa | B36: Apuleia leiocarpa (Vogel) J.F.Macbr. | D36: (Obs.: A SEMAS faz análise de DMC em nível de espécie): DMC: diâmetro mínimo da espécie + 10 cm
A37: Jarana | B37: Lecythis chartacea O.Berg | D37: 6 - Diâmetro Mínimo de Corte (DMC) - IN IBAMA 27/2024:
A38: Jatobá | B38: Hymenaea courbaril L.
A39: Louro | B39: Ocotea cymbarum Kunth | D39: Gênero | E39: FOA/FE/S/C | G39: FOD
A40: Maçaranduba | B40: Manilkara huberi (Ducke) Chevalier | E40: DMC | F40: IME | G40: DMC | H40: IME
A41: Muiracatiara | B41: Astronium lecointei Ducke | D41: Handroanthus | E41: 60 | F41: 70 | G41: 70 | H41: 70
A42: Orelha-De-Macaco | B42: Parkia pendula (Willd.) Benth. ex Walp. | D42: Tabebuia | E42: 60 | F42: 70 | G42: 70 | H42: 70
A43: Pequi | B43: Caryocar villosum (Aubl.) Pers. | D43: Dipteryx | E43: 60 | F43: 75 | G43: 80 | H43: 75
A44: Quarubarana | B44: Erisma uncinatum Warm. | D44: Cedrela | E44: 55 | F44: 70 | G44: 70 | H44: 50
A45: Sapucaia | B45: Lecythis pisonis Cambess. | D45: FOA = Floresta Ombrófila Aberta/FE = Floresta Estacional/S = Savana/C = Campinarana
A46: Tamburi | B46: Enterolobium contortisiliquum (Vell.) Morong | D46: FOD = Floresta Ombrófila Densa
A47: Tauari | B47: Couratari guianensis Aubl. | D47: DMC = Diâmetro Mínimo de Corte, em cm
A48: Taxi | B48: Tachigali myrmecophila Ducke | D48: IME = Intensidade Máxima de Exploração, em %
A49: Timborana | B49: Piptadenia suaveolens Miq.
D51: Resolução CONAMA nº 406 de 02 de fevereiro de 2009
D52: Instrução Normativa/IBAMA nº 28 de 10 de dezembro de 2024
A54: 👉 PASSO 2: Considere as seguintes Áreas de Efetiva Exploração Florestal por Unidade de Trabalho (UT): (Análise Geotecnológica)
A56: UT | B56: Área de efetiva exploração da UT (ha)
A57: 1 | B57: 294.2697
A58: 2 | B58: 277.2759
A59: Total | B59: =SUBTOTAL(109,Tabela148[Área de efetiva exploração da UT (ha)]) -> 571.5456
...

Sheet DADOS-ESPECIES
A1: Nome Vulgar | B1: Nome Científico | C1: Família | D1: Ameaçada
A2: ACAPU | B2: Vouacapoua americana Aubl. | C2: Fabaceae | D2: Protegida
A3: AMARELINHO | B3: Euxylophora paraensis Huber | C3: Rutaceae | D3: Protegida
A4: CASTANHEIRA | B4: Bertholletia excelsa Humb. & Bonpl. | C4: Lecythidaceae | D4: Protegida
A5: CASTANHEIRA-DO-PARÁ | B5: Bertholletia excelsa Humb. & Bonpl. | C5: Lecythidaceae | D5: Protegida
A6: LOURO-TAMAQUARÉ | B6: Dimorphandra wilsonii Rizzini | C6: Lauraceae | D6: Protegida
A7: MAMARANA | B7: Catostemma albuquerquei Paula | C7: Malvaceae | D7: Protegida
A8: MOGNO | B8: Swietenia macrophylla King. | C8: Meliaceae | D8: Protegida
A9: AMARELÃO | B9: Apuleia leiocarpa (Vogel) J.F.Macbr. | C9: Fabaceae | D9: Vulneravel
A10: BRAÚNA | B10: Melanoxylon brauna Schott | C10: Fabaceae | D10: Vulneravel
A11: CEDRO | B11: Cedrela fissilis Vell. | C11: Meliaceae | D11: Vulneravel
A12: CEDRO-VERMELHO | B12: Cedrela odorata L. | C12: Meliaceae | D12: Vulneravel
... A371: MARIMARI | B371: Couepia bracteosa Benth. | C371: Chrysobalanaceae | D371: Não

Sheet AEEF-UT
A1: UT | B1: AEEF-UT | C1: Unidade
A2: 1 | B2: 294.2697 | C2: ha
A3: 2 | B3: 277.2759 | C3: ha
A6: AEEF-UT: Área de Efetiva Exploração Florestal da UT

Sheet CD
A1: DAPmin | B1: Classe
A2: 0 | B2: LASCAS
A3: 10 | B3: LENHA
A4: 35 | B4: TORETE
A5: 50 | B5: TORA
A7: Classe diamétrica: classificação dos indivíduos conforme o diâmetro à altura do peito (DAP)
A9: Tora: DAP ≥ 50 cm;
A10: Torete: 35 ≤ DAP ≤ 49,99;
A11: Lenha: 10 ≤ DAP ≤ 34,99; e
A12: Lascas: DAP >10 < 50 (Confuso! Vamos admitir que "LASCAS" são individuos com DAP < 10 cm)
A14: Portaria/SEMAS nº 39 de 14 de Janeiro de 2025 (Estabelece o modelo padronizado para apresentação dos arquivos digitais de inventário florestal)

Sheet DD
A1: LI | B1: Classe
A2: 30 | B2: 30├ 40
A3: 40 | B3: 40├ 50
A4: 50 | B4: 50├ 60
A5: 60 | B5: 60├ 70
A6: 70 | B6: 70├ 80
A7: 80 | B7: 80├ 90
A8: 90 | B8: 90├ 100
A9: 100 | B9: 100├ 110
A10: 110 | B10: 110├ 120
A11: 120 | B11: 120├ 130
A12: 130 | B12: 130├ 140
A13: 140 | B13: 140├ 150
... A29: 300 | B29: 300├ 310

Sheet IN28
B1: Tipologia Florestal
B2: FOA/FE/S/C | D2: FOD
A4: Gênero | B4: DMC | C4: IME | D4: DMC2 | E4: IME2
A5: Handroanthus | B5: 60 | C5: 70 | D5: 70 | E5: 70
A6: Tabebuia | B6: 60 | C6: 70 | D6: 70 | E6: 70
A7: Dipteryx | B7: 60 | C7: 75 | D7: 80 | E7: 75
A8: Cedrela | B8: 55 | C8: 70 | D8: 70 | E8: 50
A10: FOA = Floresta Ombrófila Aberta
A11: FE = Floresta Estacional
A12: S = Savana
A13: C = Campinarana
A14: FOD = Floresta Ombrófila Densa

Sheet IF-100%
A1: N° UPA | B1: N° UT | C1: N° FAIXA | D1: Nº ÁRVORE | E1: NOME CIENTIFICO | F1: NOME COMUM | G1: CAP (cm) | H1: DAP (cm) | I1: H (m) | J1: g (m²) | K1: v (m³) | L1: QF | M1: LONGITUDE | N1: LATITUDE | O1: CATEGORIA | P1: CLASSE DIAMETRICA | Q1: DISTRIBUIÇÃO DIAMETRICA | R1: GÊNERO | S1: TIPO DE VEGETAÇÃO | T1: Dmin (cm) | U1: DMCE (cm) | V1: COMPARE | W1: DmaxC | X1: AMEAÇADA | Y1: COMERCIAIS | Z1: G (m²/ha) (571,5456 ha) | AA1: v (m³/ha) (571,5456 ha)
A2: 1 | B2: 1 | C2: 1 | D2: 1 | E2: =VLOOKUP(CENSO[[#This Row],[NOME COMUM]],ESPECIES[],2,FALSE) -> Etaballia guianensis Benth. | F2: Mututi | G2: 130 | H2: =CENSO[[#This Row],[CAP (cm)]]/PI() -> 41.380285 | I2: 11 | J2: =(PI()*(CENSO[[#This Row],[DAP (cm)]]^2))/40000 -> 0.13448593 | K2: =CENSO[[#This Row],[g (m²)]]*CENSO[[#This Row],[H (m)]]*0.7 -> 1.0355416 | L2: 1 | M2: 368862.1 | N2: 9709538.5 | O2: Remanescente | P2: =VLOOKUP(CENSO[[#This Row],[DAP (cm)]],CD[],2,TRUE) -> TORETE | Q2: =VLOOKUP(CENSO[[#This Row],[DAP (cm)]],DD[],2,TRUE) -> 40├ 50 | R2: {=INDEX(_xlfn.TEXTSPLIT(CENSO[[#This Row],[NOME CIENTIFICO]]," "),1)} -> Etaballia | S2: FOD | T2: =_xlfn.MINIFS(CENSO[DAP (cm)],CENSO[NOME CIENTIFICO],CENSO[[#This Row],[NOME CIENTIFICO]]) -> 41.380285 | U2: =IF( OR(CENSO[[#This Row],[GÊNERO]]="Handroanthus",CENSO[[#This Row],[GÊNERO]]="Tabebuia",CENSO[[#This Row],[GÊNERO]]="Dipteryx",CENSO[[#This Row],[GÊNERO]]="Cedrela"), IF( OR(CENSO[[#This Row],[TIPO DE VEGETAÇÃO]]="FOA",CENSO[[#This Row],[TIPO DE VEGETAÇÃO]]="FE",CENSO[[#This Row],[TIPO DE VEGETAÇÃO]]="S",CENSO[[#This Row],[TIPO DE VEGETAÇÃO]]="C"), VLOOKUP(CENSO[[#This Row],[GÊNERO]],IN[],2,FALSE), IF( CENSO[[#This Row],[TIPO DE VEGETAÇÃO]]="FOD", VLOOKUP(CENSO[[#This Row],[GÊNERO]],IN[],4,FALSE), "" ) ), IF( CENSO[[#This Row],[Dmin (cm)]]<40, 50, CENSO[[#This Row],[Dmin (cm)]]+10 ) ) -> 51.380285 | V2: =IF(CENSO[[#This Row],[DAP (cm)]]<CENSO[[#This Row],[DMCE (cm)]],"DAP < DMCE","DAP ≥ DMCE") -> DAP < DMCE | W2: =IF(CENSO[[#This Row],[DAP (cm)]]>200, "Superior", "Inferior") -> Inferior | X2: =VLOOKUP(CENSO[[#This Row],[NOME COMUM]],ESPECIES[],4,FALSE) -> Não | Y2: =IF(IFERROR(VLOOKUP(CENSO[[#This Row],[NOME COMUM]],COMERCIAIS[],2, FALSE), "Não") <> "Não", "Sim", "Não") -> Não | Z2: =CENSO[[#This Row],[g (m²)]]/SUM(AEEF[AEEF-UT]) -> 0.00023530218 | AA2: =CENSO[[#This Row],[v (m³)]]/SUM(AEEF[AEEF-UT]) -> 0.0018118268
A3: 1 | B3: 1 | C3: 1 | D3: 2 | E3: =VLOOKUP(CENSO[[#This Row],[NOME COMUM]],ESPECIES[],2,FALSE) -> Pouteria sp. | F3: Jará | G3: 160 | H3: =CENSO[[#This Row],[CAP (cm)]]/PI() -> 50.929582 | I3: 13 | J3: =(PI()*(CENSO[[#This Row],[DAP (cm)]]^2))/40000 -> 0.20371833 | K3: =CENSO[[#This Row],[g (m²)]]*CENSO[[#This Row],[H (m)]]*0.7 -> 1.8538368 | L3: 2 | M3: 368857.7 | N3: 9709534.4 | O3: Matriz | P3: =VLOOKUP(CENSO[[#This Row],[DAP (cm)]],CD[],2,TRUE) -> TORA | Q3: =VLOOKUP(CENSO[[#This Row],[DAP (cm)]],DD[],2,TRUE) -> 50├ 60 | R3: {=INDEX(_xlfn.TEXTSPLIT(CENSO[[#This Row],[NOME CIENTIFICO]]," "),1)} -> Pouteria | S3: FOD | T3: =_xlfn.MINIFS(CENSO[DAP (cm)],CENSO[NOME CIENTIFICO],CENSO[[#This Row],[NOME CIENTIFICO]]) -> 39.788736 | U3: =IF( OR(CENSO[[#This Row],[GÊNERO]]="Handroanthus",CENSO[[#This Row],[GÊNERO]]="Tabebuia",CENSO[[#This Row],[GÊNERO]]="Dipteryx",CENSO[[#This Row],[GÊNERO]]="Cedrela"), IF( OR(CENSO[[#This Row],[TIPO DE VEGETAÇÃO]]="FOA",CENSO[[#This Row],[TIPO DE VEGETAÇÃO]]="FE",CENSO[[#This Row],[TIPO DE VEGETAÇÃO]]="S",CENSO[[#This Row],[TIPO DE VEGETAÇÃO]]="C"), VLOOKUP(CENSO[[#This Row],[GÊNERO]],IN[],2,FALSE), IF( CENSO[[#This Row],[TIPO DE VEGETAÇÃO]]="FOD", VLOOKUP(CENSO[[#This Row],[GÊNERO]],IN[],4,FALSE), "" ) ), IF( CENSO[[#This Row],[Dmin (cm)]]<40, 50, CENSO[[#This Row],[Dmin (cm)]]+10 ) ) -> 50 | V3: =IF(CENSO[[#This Row],[DAP (cm)]]<CENSO[[#This Row],[DMCE (cm)]],"DAP < DMCE","DAP ≥ DMCE") -> DAP ≥ DMCE | W3: =IF(CENSO[[#This Row],[DAP (cm)]]>200, "Superior", "Inferior") -> Inferior | X3: =VLOOKUP(CENSO[[#This Row],[NOME COMUM]],ESPECIES[],4,FALSE) -> Não | Y3: =IF(IFERROR(VLOOKUP(CENSO[[#This Row],[NOME COMUM]],COMERCIAIS[],2, FALSE), "Não") <> "Não", "Sim", "Não") -> Não | Z3: =CENSO[[#This Row],[g (m²)]]/SUM(AEEF[AEEF-UT]) -> 0.00035643407 | AA3: =CENSO[[#This Row],[v (m³)]]/SUM(AEEF[AEEF-UT]) -> 0.0032435501
A4: 1 | B4: 1 | C4: 2 | D4: 3 | E4: =VLOOKUP(CENSO[[#This Row],[NOME COMUM]],ESPECIES[],2,FALSE) -> Parkia multijuga Benth. | F4: Fava-De-Tucupi | G4: 125 | H4: =CENSO[[#This Row],[CAP (cm)]]/PI() -> 39.788736 | I4: 16 | J4: =(PI()*(CENSO[[#This Row],[DAP (cm)]]^2))/40000 -> 0.1243398 | K4: =CENSO[[#This Row],[g (m²)]]*CENSO[[#This Row],[H (m)]]*0.7 -> 1.3926058 | L4: 2 | M4: 368823 | N4: 9709517.4 | O4: Remanescente | P4: =VLOOKUP(CENSO[[#This Row],[DAP (cm)]],CD[],2,TRUE) -> TORETE | Q4: =VLOOKUP(CENSO[[#This Row],[DAP (cm)]],DD[],2,TRUE) -> 30├ 40 | R4: {=INDEX(_xlfn.TEXTSPLIT(CENSO[[#This Row],[NOME CIENTIFICO]]," "),1)} -> Parkia | S4: FOD | T4: =_xlfn.MINIFS(CENSO[DAP (cm)],CENSO[NOME CIENTIFICO],CENSO[[#This Row],[NOME CIENTIFICO]]) -> 39.788736 | U4: =IF( OR(CENSO[[#This Row],[GÊNERO]]="Handroanthus",CENSO[[#This Row],[GÊNERO]]="Tabebuia",CENSO[[#This Row],[GÊNERO]]="Dipteryx",CENSO[[#This Row],[GÊNERO]]="Cedrela"), IF( OR(CENSO[[#This Row],[TIPO DE VEGETAÇÃO]]="FOA",CENSO[[#This Row],[TIPO DE VEGETAÇÃO]]="FE",CENSO[[#This Row],[TIPO DE VEGETAÇÃO]]="S",CENSO[[#This Row],[TIPO DE VEGETAÇÃO]]="C"), VLOOKUP(CENSO[[#This Row],[GÊNERO]],IN[],2,FALSE), IF( CENSO[[#This Row],[TIPO DE VEGETAÇÃO]]="FOD", VLOOKUP(CENSO[[#This Row],[GÊNERO]],IN[],4,FALSE), "" ) ), IF( CENSO[[#This Row],[Dmin (cm)]]<40, 50, CENSO[[#This Row],[Dmin (cm)]]+10 ) ) -> 50 | V4: =IF(CENSO[[#This Row],[DAP (cm)]]<CENSO[[#This Row],[DMCE (cm)]],"DAP < DMCE","DAP ≥ DMCE") -> DAP < DMCE | W4: =IF(CENSO[[#This Row],[DAP (cm)]]>200, "Superior", "Inferior") -> Inferior | X4: =VLOOKUP(CENSO[[#This Row],[NOME COMUM]],ESPECIES[],4,FALSE) -> Não | Y4: =IF(IFERROR(VLOOKUP(CENSO[[#This Row],[NOME COMUM]],COMERCIAIS[],2, FALSE), "Não") <> "Não", "Sim", "Não") -> Não | Z4: =CENSO[[#This Row],[g (m²)]]/SUM(AEEF[AEEF-UT]) -> 0.00021755009 | AA4: =CENSO[[#This Row],[v (m³)]]/SUM(AEEF[AEEF-UT]) -> 0.0024365611
A5: 1 | B5: 1 | C5: 2 | D5: 4 | E5: =VLOOKUP(CENSO[[#This Row],[NOME COMUM]],ESPECIES[],2,FALSE) -> Inga paraensis Ducke | F5: Ingá | G5: 131 | H5: =CENSO[[#This Row],[CAP (cm)]]/PI() -> 41.698595 | I5: 14 | J5: =(PI()*(CENSO[[#This Row],[DAP (cm)]]^2))/40000 -> 0.1365629 | K5: =CENSO[[#This Row],[g (m²)]]*CENSO[[#This Row],[H (m)]]*0.7 -> 1.3383164 | L5: 2 | M5: 368801.3 | N5: 9709506.9 | O5: Remanescente | P5: =VLOOKUP(CENSO[[#This Row],[DAP (cm)]],CD[],2,TRUE) -> TORETE | Q5: =VLOOKUP(CENSO[[#This Row],[DAP (cm)]],DD[],2,TRUE) -> 40├ 50 | R5: {=INDEX(_xlfn.TEXTSPLIT(CENSO[[#This Row],[NOME CIENTIFICO]]," "),1)} -> Inga | S5: FOD | T5: =_xlfn.MINIFS(CENSO[DAP (cm)],CENSO[NOME CIENTIFICO],CENSO[[#This Row],[NOME CIENTIFICO]]) -> 41.380285 | U5: =IF( OR(CENSO[[#This Row],[GÊNERO]]="Handroanthus",CENSO[[#This Row],[GÊNERO]]="Tabebuia",CENSO[[#This Row],[GÊNERO]]="Dipteryx",CENSO[[#This Row],[GÊNERO]]="Cedrela"), IF( OR(CENSO[[#This Row],[TIPO DE VEGETAÇÃO]]="FOA",CENSO[[#This Row],[TIPO DE VEGETAÇÃO]]="FE",CENSO[[#This Row],[TIPO DE VEGETAÇÃO]]="S",CENSO[[#This Row],[TIPO DE VEGETAÇÃO]]="C"), VLOOKUP(CENSO[[#This Row],[GÊNERO]],IN[],2,FALSE), IF( CENSO[[#This Row],[TIPO DE VEGETAÇÃO]]="FOD", VLOOKUP(CENSO[[#This Row],[GÊNERO]],IN[],4,FALSE), "" ) ), IF( CENSO[[#This Row],[Dmin (cm)]]<40, 50, CENSO[[#This Row],[Dmin (cm)]]+10 ) ) -> 51.380285 | V5: =IF(CENSO[[#This Row],[DAP (cm)]]<CENSO[[#This Row],[DMCE (cm)]],"DAP < DMCE","DAP ≥ DMCE") -> DAP < DMCE | W5: =IF(CENSO[[#This Row],[DAP (cm)]]>200, "Superior", "Inferior") -> Inferior | X5: =VLOOKUP(CENSO[[#This Row],[NOME COMUM]],ESPECIES[],4,FALSE) -> Não | Y5: =IF(IFERROR(VLOOKUP(CENSO[[#This Row],[NOME COMUM]],COMERCIAIS[],2, FALSE), "Não") <> "Não", "Sim", "Não") -> Não | Z5: =CENSO[[#This Row],[g (m²)]]/SUM(AEEF[AEEF-UT]) -> 0.00023893614 | AA5: =CENSO[[#This Row],[v (m³)]]/SUM(AEEF[AEEF-UT]) -> 0.0023415742
A6: 1 | B6: 1 | C6: 2 | D6: 5 | E6: =VLOOKUP(CENSO[[#This Row],[NOME COMUM]],ESPECIES[],2,FALSE) -> Dialium guianense (Aubl.) Sandwith | F6: Pororoca | G6: 252 | H6: =CENSO[[#This Row],[CAP (cm)]]/PI() -> 80.214091 | I6: 17 | J6: =(PI()*(CENSO[[#This Row],[DAP (cm)]]^2))/40000 -> 0.50534878 | K6: =CENSO[[#This Row],[g (m²)]]*CENSO[[#This Row],[H (m)]]*0.7 -> 6.0136504 | L6: 1 | M6: 368800.3 | N6: 9709495.7 | O6: Matriz | P6: =VLOOKUP(CENSO[[#This Row],[DAP (cm)]],CD[],2,TRUE) -> TORA | Q6: =VLOOKUP(CENSO[[#This Row],[DAP (cm)]],DD[],2,TRUE) -> 80├ 90 | R6: {=INDEX(_xlfn.TEXTSPLIT(CENSO[[#This Row],[NOME CIENTIFICO]]," "),1)} -> Dialium | S6: FOD | T6: =_xlfn.MINIFS(CENSO[DAP (cm)],CENSO[NOME CIENTIFICO],CENSO[[#This Row],[NOME CIENTIFICO]]) -> 42.335215 | U6: =IF( OR(CENSO[[#This Row],[GÊNERO]]="Handroanthus",CENSO[[#This Row],[GÊNERO]]="Tabebuia",CENSO[[#This Row],[GÊNERO]]="Dipteryx",CENSO[[#This Row],[GÊNERO]]="Cedrela"), IF( OR(CENSO[[#This Row],[TIPO DE VEGETAÇÃO]]="FOA",CENSO[[#This Row],[TIPO DE VEGETAÇÃO]]="FE",CENSO[[#This Row],[TIPO DE VEGETAÇÃO]]="S",CENSO[[#This Row],[TIPO DE VEGETAÇÃO]]="C"), VLOOKUP(CENSO[[#This Row],[GÊNERO]],IN[],2,FALSE), IF( CENSO[[#This Row],[TIPO DE VEGETAÇÃO]]="FOD", VLOOKUP(CENSO[[#This Row],[GÊNERO]],IN[],4,FALSE), "" ) ), IF( CENSO[[#This Row],[Dmin (cm)]]<40, 50, CENSO[[#This Row],[Dmin (cm)]]+10 ) ) -> 52.335215 | V6: =IF(CENSO[[#This Row],[DAP (cm)]]<CENSO[[#This Row],[DMCE (cm)]],"DAP < DMCE","DAP ≥ DMCE") -> DAP ≥ DMCE | W6: =IF(CENSO[[#This Row],[DAP (cm)]]>200, "Superior", "Inferior") -> Inferior | X6: =VLOOKUP(CENSO[[#This Row],[NOME COMUM]],ESPECIES[],4,FALSE) -> Não | Y6: =IF(IFERROR(VLOOKUP(CENSO[[#This Row],[NOME COMUM]],COMERCIAIS[],2, FALSE), "Não") <> "Não", "Sim", "Não") -> Não | Z6: =CENSO[[#This Row],[g (m²)]]/SUM(AEEF[AEEF-UT]) -> 0.00088417928 | AA6: =CENSO[[#This Row],[v (m³)]]/SUM(AEEF[AEEF-UT]) -> 0.010521733
A7: 1 | B7: 1 | C7: 2 | D7: 6 | E7: =VLOOKUP(CENSO[[#This Row],[NOME COMUM]],ESPECIES[],2,FALSE) -> Tachigali myrmecophila Ducke | F7: Taxi | G7: 252 | H7: =CENSO[[#This Row],[CAP (cm)]]/PI() -> 80.214091 | I7: 17 | J7: =(PI()*(CENSO[[#This Row],[DAP (cm)]]^2))/40000 -> 0.50534878 | K7: =CENSO[[#This Row],[g (m²)]]*CENSO[[#This Row],[H (m)]]*0.7 -> 6.0136504 | L7: 1 | M7: 368799.6 | N7: 9709494.9 | O7: Matriz | P7: =VLOOKUP(CENSO[[#This Row],[DAP (cm)]],CD[],2,TRUE) -> TORA | Q7: =VLOOKUP(CENSO[[#This Row],[DAP (cm)]],DD[],2,TRUE) -> 80├ 90 | R7: {=INDEX(_xlfn.TEXTSPLIT(CENSO[[#This Row],[NOME CIENTIFICO]]," "),1)} -> Tachigali | S7: FOD | T7: =_xlfn.MINIFS(CENSO[DAP (cm)],CENSO[NOME CIENTIFICO],CENSO[[#This Row],[NOME CIENTIFICO]]) -> 39.152116 | U7: =IF( OR(CENSO[[#This Row],[GÊNERO]]="Handroanthus",CENSO[[#This Row],[GÊNERO]]="Tabebuia",CENSO[[#This Row],[GÊNERO]]="Dipteryx",CENSO[[#This Row],[GÊNERO]]="Cedrela"), IF( OR(CENSO[[#This Row],[TIPO DE VEGETAÇÃO]]="FOA",CENSO[[#This Row],[TIPO DE VEGETAÇÃO]]="FE",CENSO[[#This Row],[TIPO DE VEGETAÇÃO]]="S",CENSO[[#This Row],[TIPO DE VEGETAÇÃO]]="C"), VLOOKUP(CENSO[[#This Row],[GÊNERO]],IN[],2,FALSE), IF( CENSO[[#This Row],[TIPO DE VEGETAÇÃO]]="FOD", VLOOKUP(CENSO[[#This Row],[GÊNERO]],IN[],4,FALSE), "" ) ), IF( CENSO[[#This Row],[Dmin (cm)]]<40, 50, CENSO[[#This Row],[Dmin (cm)]]+10 ) ) -> 50 | V7: =IF(CENSO[[#This Row],[DAP (cm)]]<CENSO[[#This Row],[DMCE (cm)]],"DAP < DMCE","DAP ≥ DMCE") -> DAP ≥ DMCE | W7: =IF(CENSO[[#This Row],[DAP (cm)]]>200, "Superior", "Inferior") -> Inferior | X7: =VLOOKUP(CENSO[[#This Row],[NOME COMUM]],ESPECIES[],4,FALSE) -> Não | Y7: =IF(IFERROR(VLOOKUP(CENSO[[#This Row],[NOME COMUM]],COMERCIAIS[],2, FALSE), "Não") <> "Não", "Sim", "Não") -> Sim | Z7: =CENSO[[#This Row],[g (m²)]]/SUM(AEEF[AEEF-UT]) -> 0.00088417928 | AA7: =CENSO[[#This Row],[v (m³)]]/SUM(AEEF[AEEF-UT]) -> 0.010521733
A8: 1 | B8: 1 | C8: 2 | D8: 7 | E8: =VLOOKUP(CENSO[[#This Row],[NOME COMUM]],ESPECIES[],2,FALSE) -> Inga paraensis Ducke | F8: Ingá | G8: 131 | H8: =CENSO[[#This Row],[CAP (cm)]]/PI() -> 41.698595 | I8: 17 | J8: =(PI()*(CENSO[[#This Row],[DAP (cm)]]^2))/40000 -> 0.1365629 | K8: =CENSO[[#This Row],[g (m²)]]*CENSO[[#This Row],[H (m)]]*0.7 -> 1.6250985 | L8: 2 | M8: 368806.5 | N8: 9709487.4 | O8: Remanescente | P8: =VLOOKUP(CENSO[[#This Row],[DAP (cm)]],CD[],2,TRUE) -> TORETE | Q8: =VLOOKUP(CENSO[[#This Row],[DAP (cm)]],DD[],2,TRUE) -> 40├ 50 | R8: {=INDEX(_xlfn.TEXTSPLIT(CENSO[[#This Row],[NOME CIENTIFICO]]," "),1)} -> Inga | S8: FOD | T8: =_xlfn.MINIFS(CENSO[DAP (cm)],CENSO[NOME CIENTIFICO],CENSO[[#This Row],[NOME CIENTIFICO]]) -> 41.380285 | U8: =IF( OR(CENSO[[#This Row],[GÊNERO]]="Handroanthus",CENSO[[#This Row],[GÊNERO]]="Tabebuia",CENSO[[#This Row],[GÊNERO]]="Dipteryx",CENSO[[#This Row],[GÊNERO]]="Cedrela"), IF( OR(CENSO[[#This Row],[TIPO DE VEGETAÇÃO]]="FOA",CENSO[[#This Row],[TIPO DE VEGETAÇÃO]]="FE",CENSO[[#This Row],[TIPO DE VEGETAÇÃO]]="S",CENSO[[#This Row],[TIPO DE VEGETAÇÃO]]="C"), VLOOKUP(CENSO[[#This Row],[GÊNERO]],IN[],2,FALSE), IF( CENSO[[#This Row],[TIPO DE VEGETAÇÃO]]="FOD", VLOOKUP(CENSO[[#This Row],[GÊNERO]],IN[],4,FALSE), "" ) ), IF( CENSO[[#This Row],[Dmin (cm)]]<40, 50, CENSO[[#This Row],[Dmin (cm)]]+10 ) ) -> 51.380285 | V8: =IF(CENSO[[#This Row],[DAP (cm)]]<CENSO[[#This Row],[DMCE (cm)]],"DAP < DMCE","DAP ≥ DMCE") -> DAP < DMCE | W8: =IF(CENSO[[#This Row],[DAP (cm)]]>200, "Superior", "Inferior") -> Inferior | X8: =VLOOKUP(CENSO[[#This Row],[NOME COMUM]],ESPECIES[],4,FALSE) -> Não | Y8: =IF(IFERROR(VLOOKUP(CENSO[[#This Row],[NOME COMUM]],COMERCIAIS[],2, FALSE), "Não") <> "Não", "Sim", "Não") -> Não | Z8: =CENSO[[#This Row],[g (m²)]]/SUM(AEEF[AEEF-UT]) -> 0.00023893614 | AA8: =CENSO[[#This Row],[v (m³)]]/SUM(AEEF[AEEF-UT]) -> 0.0028433401
A9: 1 | B9: 1 | C9: 3 | D9: 8 | E9: =VLOOKUP(CENSO[[#This Row],[NOME COMUM]],ESPECIES[],2,FALSE) -> Dimorphandra multiflora Ducke | F9: Fava | G9: 132 | H9: =CENSO[[#This Row],[CAP (cm)]]/PI() -> 42.016905 | I9: 13 | J9: =(PI()*(CENSO[[#This Row],[DAP (cm)]]^2))/40000 -> 0.13865579 | K9: =CENSO[[#This Row],[g (m²)]]*CENSO[[#This Row],[H (m)]]*0.7 -> 1.2617677 | L9: 1 | M9: 368791.7 | N9: 9709450.2 | O9: Remanescente | P9: =VLOOKUP(CENSO[[#This Row],[DAP (cm)]],CD[],2,TRUE) -> TORETE | Q9: =VLOOKUP(CENSO[[#This Row],[DAP (cm)]],DD[],2,TRUE) -> 40├ 50 | R9: {=INDEX(_xlfn.TEXTSPLIT(CENSO[[#This Row],[NOME CIENTIFICO]]," "),1)} -> Dimorphandra | S9: FOD | T9: =_xlfn.MINIFS(CENSO[DAP (cm)],CENSO[NOME CIENTIFICO],CENSO[[#This Row],[NOME CIENTIFICO]]) -> 39.788736 | U9: =IF( OR(CENSO[[#This Row],[GÊNERO]]="Handroanthus",CENSO[[#This Row],[GÊNERO]]="Tabebuia",CENSO[[#This Row],[GÊNERO]]="Dipteryx",CENSO[[#This Row],[GÊNERO]]="Cedrela"), IF( OR(CENSO[[#This Row],[TIPO DE VEGETAÇÃO]]="FOA",CENSO[[#This Row],[TIPO DE VEGETAÇÃO]]="FE",CENSO[[#This Row],[TIPO DE VEGETAÇÃO]]="S",CENSO[[#This Row],[TIPO DE VEGETAÇÃO]]="C"), VLOOKUP(CENSO[[#This Row],[GÊNERO]],IN[],2,FALSE), IF( CENSO[[#This Row],[TIPO DE VEGETAÇÃO]]="FOD", VLOOKUP(CENSO[[#This Row],[GÊNERO]],IN[],4,FALSE), "" ) ), IF( CENSO[[#This Row],[Dmin (cm)]]<40, 50, CENSO[[#This Row],[Dmin (cm)]]+10 ) ) -> 50 | V9: =IF(CENSO[[#This Row],[DAP (cm)]]<CENSO[[#This Row],[DMCE (cm)]],"DAP < DMCE","DAP ≥ DMCE") -> DAP < DMCE | W9: =IF(CENSO[[#This Row],[DAP (cm)]]>200, "Superior", "Inferior") -> Inferior | X9: =VLOOKUP(CENSO[[#This Row],[NOME COMUM]],ESPECIES[],4,FALSE) -> Não | Y9: =IF(IFERROR(VLOOKUP(CENSO[[#This Row],[NOME COMUM]],COMERCIAIS[],2, FALSE), "Não") <> "Não", "Sim", "Não") -> Não | Z9: =CENSO[[#This Row],[g (m²)]]/SUM(AEEF[AEEF-UT]) -> 0.00024259794 | AA9: =CENSO[[#This Row],[v (m³)]]/SUM(AEEF[AEEF-UT]) -> 0.0022076413
A10: 1 | B10: 1 | C10: 3 | D10: 9 | E10: =VLOOKUP(CENSO[[#This Row],[NOME COMUM]],ESPECIES[],2,FALSE) -> Aspidosperma carapanauba Pichon. | F10: Carapanaúba | G10: 222 | H10: =CENSO[[#This Row],[CAP (cm)]]/PI() -> 70.664795 | I10: 17 | J10: =(PI()*(CENSO[[#This Row],[DAP (cm)]]^2))/40000 -> 0.39218961 | K10: =CENSO[[#This Row],[g (m²)]]*CENSO[[#This Row],[H (m)]]*0.7 -> 4.6670564 | L10: 3 | M10: 368808.6 | N10: 9709475.9 | O10: Remanescente 2 | P10: =VLOOKUP(CENSO[[#This Row],[DAP (cm)]],CD[],2,TRUE) -> TORA | Q10: =VLOOKUP(CENSO[[#This Row],[DAP (cm)]],DD[],2,TRUE) -> 70├ 80 | R10: {=INDEX(_xlfn.TEXTSPLIT(CENSO[[#This Row],[NOME CIENTIFICO]]," "),1)} -> Aspidosperma | S10: FOD | T10: =_xlfn.MINIFS(CENSO[DAP (cm)],CENSO[NOME CIENTIFICO],CENSO[[#This Row],[NOME CIENTIFICO]]) -> 47.109863 | U10: =IF( OR(CENSO[[#This Row],[GÊNERO]]="Handroanthus",CENSO[[#This Row],[GÊNERO]]="Tabebuia",CENSO[[#This Row],[GÊNERO]]="Dipteryx",CENSO[[#This Row],[GÊNERO]]="Cedrela"), IF( OR(CENSO[[#This Row],[TIPO DE VEGETAÇÃO]]="FOA",CENSO[[#This Row],[TIPO DE VEGETAÇÃO]]="FE",CENSO[[#This Row],[TIPO DE VEGETAÇÃO]]="S",CENSO[[#This Row],[TIPO DE VEGETAÇÃO]]="C"), VLOOKUP(CENSO[[#This Row],[GÊNERO]],IN[],2,FALSE), IF( CENSO[[#This Row],[TIPO DE VEGETAÇÃO]]="FOD", VLOOKUP(CENSO[[#This Row],[GÊNERO]],IN[],4,FALSE), "" ) ), IF( CENSO[[#This Row],[Dmin (cm)]]<40, 50, CENSO[[#This Row],[Dmin (cm)]]+10 ) ) -> 57.109863 | V10: =IF(CENSO[[#This Row],[DAP (cm)]]<CENSO[[#This Row],[DMCE (cm)]],"DAP < DMCE","DAP ≥ DMCE") -> DAP ≥ DMCE | W10: =IF(CENSO[[#This Row],[DAP (cm)]]>200, "Superior", "Inferior") -> Inferior | X10: =VLOOKUP(CENSO[[#This Row],[NOME COMUM]],ESPECIES[],4,FALSE) -> Não | Y10: =IF(IFERROR(VLOOKUP(CENSO[[#This Row],[NOME COMUM]],COMERCIAIS[],2, FALSE), "Não") <> "Não", "Sim", "Não") -> Não | Z10: =CENSO[[#This Row],[g (m²)]]/SUM(AEEF[AEEF-UT]) -> 0.00068619129 | AA10: =CENSO[[#This Row],[v (m³)]]/SUM(AEEF[AEEF-UT]) -> 0.0081656763
A11: 1 | B11: 1 | C11: 3 | D11: 10 | E11: =VLOOKUP(CENSO[[#This Row],[NOME COMUM]],ESPECIES[],2,FALSE) -> Licania octandra | F11: Casca Seca | G11: 165 | H11: =CENSO[[#This Row],[CAP (cm)]]/PI() -> 52.521131 | I11: 16 | J11: =(PI()*(CENSO[[#This Row],[DAP (cm)]]^2))/40000 -> 0.21664967 | K11: =CENSO[[#This Row],[g (m²)]]*CENSO[[#This Row],[H (m)]]*0.7 -> 2.4264763 | L11: 1 | M11: 368790 | N11: 9709461.1 | O11: Matriz | P11: =VLOOKUP(CENSO[[#This Row],[DAP (cm)]],CD[],2,TRUE) -> TORA | Q11: =VLOOKUP(CENSO[[#This Row],[DAP (cm)]],DD[],2,TRUE) -> 50├ 60 | R11: {=INDEX(_xlfn.TEXTSPLIT(CENSO[[#This Row],[NOME CIENTIFICO]]," "),1)} -> Licania | S11: FOD | T11: =_xlfn.MINIFS(CENSO[DAP (cm)],CENSO[NOME CIENTIFICO],CENSO[[#This Row],[NOME CIENTIFICO]]) -> 41.380285 | U11: =IF( OR(CENSO[[#This Row],[GÊNERO]]="Handroanthus",CENSO[[#This Row],[GÊNERO]]="Tabebuia",CENSO[[#This Row],[GÊNERO]]="Dipteryx",CENSO[[#This Row],[GÊNERO]]="Cedrela"), IF( OR(CENSO[[#This Row],[TIPO DE VEGETAÇÃO]]="FOA",CENSO[[#This Row],[TIPO DE VEGETAÇÃO]]="FE",CENSO[[#This Row],[TIPO DE VEGETAÇÃO]]="S",CENSO[[#This Row],[TIPO DE VEGETAÇÃO]]="C"), VLOOKUP(CENSO[[#This Row],[GÊNERO]],IN[],2,FALSE), IF( CENSO[[#This Row],[TIPO DE VEGETAÇÃO]]="FOD", VLOOKUP(CENSO[[#This Row],[GÊNERO]],IN[],4,FALSE), "" ) ), IF( CENSO[[#This Row],[Dmin (cm)]]<40, 50, CENSO[[#This Row],[Dmin (cm)]]+10 ) ) -> 51.380285 | V11: =IF(CENSO[[#This Row],[DAP (cm)]]<CENSO[[#This Row],[DMCE (cm)]],"DAP < DMCE","DAP ≥ DMCE") -> DAP ≥ DMCE | W11: =IF(CENSO[[#This Row],[DAP (cm)]]>200, "Superior", "Inferior") -> Inferior | X11: =VLOOKUP(CENSO[[#This Row],[NOME COMUM]],ESPECIES[],4,FALSE) -> Não | Y11: =IF(IFERROR(VLOOKUP(CENSO[[#This Row],[NOME COMUM]],COMERCIAIS[],2, FALSE), "Não") <> "Não", "Sim", "Não") -> Não | Z11: =CENSO[[#This Row],[g (m²)]]/SUM(AEEF[AEEF-UT]) -> 0.00037905928 | AA11: =CENSO[[#This Row],[v (m³)]]/SUM(AEEF[AEEF-UT]) -> 0.004245464
A12: 1 | B12: 1 | C12: 3 | D12: 11 | E12: =VLOOKUP(CENSO[[#This Row],[NOME COMUM]],ESPECIES[],2,FALSE) -> Matisia paraensis Huber | F12: Cupuaçurana | G12: 228 | H12: =CENSO[[#This Row],[CAP (cm)]]/PI() -> 72.574654 | I12: 17 | J12: =(PI()*(CENSO[[#This Row],[DAP (cm)]]^2))/40000 -> 0.41367553 | K12: =CENSO[[#This Row],[g (m²)]]*CENSO[[#This Row],[H (m)]]*0.7 -> 4.9227388 | L12: 2 | M12: 368791 | N12: 9709492.1 | O12: Matriz | P12: =VLOOKUP(CENSO[[#This Row],[DAP (cm)]],CD[],2,TRUE) -> TORA | Q12: =VLOOKUP(CENSO[[#This Row],[DAP (cm)]],DD[],2,TRUE) -> 70├ 80 | R12: {=INDEX(_xlfn.TEXTSPLIT(CENSO[[#This Row],[NOME CIENTIFICO]]," "),1)} -> Matisia | S12: FOD | T12: =_xlfn.MINIFS(CENSO[DAP (cm)],CENSO[NOME CIENTIFICO],CENSO[[#This Row],[NOME CIENTIFICO]]) -> 43.926764 | U12: =IF( OR(CENSO[[#This Row],[GÊNERO]]="Handroanthus",CENSO[[#This Row],[GÊNERO]]="Tabebuia",CENSO[[#This Row],[GÊNERO]]="Dipteryx",CENSO[[#This Row],[GÊNERO]]="Cedrela"), IF( OR(CENSO[[#This Row],[TIPO DE VEGETAÇÃO]]="FOA",CENSO[[#This Row],[TIPO DE VEGETAÇÃO]]="FE",CENSO[[#This Row],[TIPO DE VEGETAÇÃO]]="S",CENSO[[#This Row],[TIPO DE VEGETAÇÃO]]="C"), VLOOKUP(CENSO[[#This Row],[GÊNERO]],IN[],2,FALSE), IF( CENSO[[#This Row],[TIPO DE VEGETAÇÃO]]="FOD", VLOOKUP(CENSO[[#This Row],[GÊNERO]],IN[],4,FALSE), "" ) ), IF( CENSO[[#This Row],[Dmin (cm)]]<40, 50, CENSO[[#This Row],[Dmin (cm)]]+10 ) ) -> 53.926764 | V12: =IF(CENSO[[#This Row],[DAP (cm)]]<CENSO[[#This Row],[DMCE (cm)]],"DAP < DMCE","DAP ≥ DMCE") -> DAP ≥ DMCE | W12: =IF(CENSO[[#This Row],[DAP (cm)]]>200, "Superior", "Inferior") -> Inferior | X12: =VLOOKUP(CENSO[[#This Row],[NOME COMUM]],ESPECIES[],4,FALSE) -> Não | Y12: =IF(IFERROR(VLOOKUP(CENSO[[#This Row],[NOME COMUM]],COMERCIAIS[],2, FALSE), "Não") <> "Não", "Sim", "Não") -> Não | Z12: =CENSO[[#This Row],[g (m²)]]/SUM(AEEF[AEEF-UT]) -> 0.00072378394 | AA12: =CENSO[[#This Row],[v (m³)]]/SUM(AEEF[AEEF-UT]) -> 0.0086130289
A13: 1 | B13: 1 | C13: 3 | D13: 12 | E13: =VLOOKUP(CENSO[[#This Row],[NOME COMUM]],ESPECIES[],2,FALSE) -> Astronium lecointei Ducke | F13: Muiracatiara | G13: 300 | H13: =CENSO[[#This Row],[CAP (cm)]]/PI() -> 95.492966 | I13: 24 | J13: =(PI()*(CENSO[[#This Row],[DAP (cm)]]^2))/40000 -> 0.71619724 | K13: =CENSO[[#This Row],[g (m²)]]*CENSO[[#This Row],[H (m)]]*0.7 -> 12.032114 | L13: 1 | M13: 368771.6 | N13: 9709481.4 | O13: Matriz | P13: =VLOOKUP(CENSO[[#This Row],[DAP (cm)]],CD[],2,TRUE) -> TORA | Q13: =VLOOKUP(CENSO[[#This Row],[DAP (cm)]],DD[],2,TRUE) -> 90├ 100 | R13: {=INDEX(_xlfn.TEXTSPLIT(CENSO[[#This Row],[NOME CIENTIFICO]]," "),1)} -> Astronium | S13: FOD | T13: =_xlfn.MINIFS(CENSO[DAP (cm)],CENSO[NOME CIENTIFICO],CENSO[[#This Row],[NOME CIENTIFICO]]) -> 40.107046 | U13: =IF( OR(CENSO[[#This Row],[GÊNERO]]="Handroanthus",CENSO[[#This Row],[GÊNERO]]="Tabebuia",CENSO[[#This Row],[GÊNERO]]="Dipteryx",CENSO[[#This Row],[GÊNERO]]="Cedrela"), IF( OR(CENSO[[#This Row],[TIPO DE VEGETAÇÃO]]="FOA",CENSO[[#This Row],[TIPO DE VEGETAÇÃO]]="FE",CENSO[[#This Row],[TIPO DE VEGETAÇÃO]]="S",CENSO[[#This Row],[TIPO DE VEGETAÇÃO]]="C"), VLOOKUP(CENSO[[#This Row],[GÊNERO]],IN[],2,FALSE), IF( CENSO[[#This Row],[TIPO DE VEGETAÇÃO]]="FOD", VLOOKUP(CENSO[[#This Row],[GÊNERO]],IN[],4,FALSE), "" ) ), IF( CENSO[[#This Row],[Dmin (cm)]]<40, 50, CENSO[[#This Row],[Dmin (cm)]]+10 ) ) -> 50.107046 | V13: =IF(CENSO[[#This Row],[DAP (cm)]]<CENSO[[#This Row],[DMCE (cm)]],"DAP < DMCE","DAP ≥ DMCE") -> DAP ≥ DMCE | W13: =IF(CENSO[[#This Row],[DAP (cm)]]>200, "Superior", "Inferior") -> Inferior | X13: =VLOOKUP(CENSO[[#This Row],[NOME COMUM]],ESPECIES[],4,FALSE) -> Não | Y13: =IF(IFERROR(VLOOKUP(CENSO[[#This Row],[NOME COMUM]],COMERCIAIS[],2, FALSE), "Não") <> "Não", "Sim", "Não") -> Sim | Z13: =CENSO[[#This Row],[g (m²)]]/SUM(AEEF[AEEF-UT]) -> 0.0012530885 | AA13: =CENSO[[#This Row],[v (m³)]]/SUM(AEEF[AEEF-UT]) -> 0.021051888
... A4937: 1 | B4937: 2 | C4937: 139 | D4937: 4937 | E4937: =VLOOKUP(CENSO[[#This Row],[NOME COMUM]],ESPECIES[],2,FALSE) -> Buchenavia capitata (Vahl) Eichler | F4937: Mirindiba | G4937: 180 | H4937: =CENSO[[#This Row],[CAP (cm)]]/PI() -> 57.29578 | I4937: 17 | J4937: =(PI()*(CENSO[[#This Row],[DAP (cm)]]^2))/40000 -> 0.25783101 | K4937: =CENSO[[#This Row],[g (m²)]]*CENSO[[#This Row],[H (m)]]*0.7 -> 3.068189 | L4937: 1 | M4937: 367666.8 | N4937: 9702700.5 | O4937: Matriz | P4937: =VLOOKUP(CENSO[[#This Row],[DAP (cm)]],CD[],2,TRUE) -> TORA | Q4937: =VLOOKUP(CENSO[[#This Row],[DAP (cm)]],DD[],2,TRUE) -> 50├ 60 | R4937: {=INDEX(_xlfn.TEXTSPLIT(CENSO[[#This Row],[NOME CIENTIFICO]]," "),1)} -> Buchenavia | S4937: FOD | T4937: =_xlfn.MINIFS(CENSO[DAP (cm)],CENSO[NOME CIENTIFICO],CENSO[[#This Row],[NOME CIENTIFICO]]) -> 41.380285 | U4937: =IF( OR(CENSO[[#This Row],[GÊNERO]]="Handroanthus",CENSO[[#This Row],[GÊNERO]]="Tabebuia",CENSO[[#This Row],[GÊNERO]]="Dipteryx",CENSO[[#This Row],[GÊNERO]]="Cedrela"), IF( OR(CENSO[[#This Row],[TIPO DE VEGETAÇÃO]]="FOA",CENSO[[#This Row],[TIPO DE VEGETAÇÃO]]="FE",CENSO[[#This Row],[TIPO DE VEGETAÇÃO]]="S",CENSO[[#This Row],[TIPO DE VEGETAÇÃO]]="C"), VLOOKUP(CENSO[[#This Row],[GÊNERO]],IN[],2,FALSE), IF( CENSO[[#This Row],[TIPO DE VEGETAÇÃO]]="FOD", VLOOKUP(CENSO[[#This Row],[GÊNERO]],IN[],4,FALSE), "" ) ), IF( CENSO[[#This Row],[Dmin (cm)]]<40, 50, CENSO[[#This Row],[Dmin (cm)]]+10 ) ) -> 51.380285 | V4937: =IF(CENSO[[#This Row],[DAP (cm)]]<CENSO[[#This Row],[DMCE (cm)]],"DAP < DMCE","DAP ≥ DMCE") -> DAP ≥ DMCE | W4937: =IF(CENSO[[#This Row],[DAP (cm)]]>200, "Superior", "Inferior") -> Inferior | X4937: =VLOOKUP(CENSO[[#This Row],[NOME COMUM]],ESPECIES[],4,FALSE) -> Não | Y4937: =IF(IFERROR(VLOOKUP(CENSO[[#This Row],[NOME COMUM]],COMERCIAIS[],2, FALSE), "Não") <> "Não", "Sim", "Não") -> Não | Z4937: =CENSO[[#This Row],[g (m²)]]/SUM(AEEF[AEEF-UT]) -> 0.00045111188 | AA4937: =CENSO[[#This Row],[v (m³)]]/SUM(AEEF[AEEF-UT]) -> 0.0053682313

Sheet LISTA-ESPECIES
A1: N° UT | B1: (Tudo)
A2: COMERCIAIS | B2: (Tudo)
A4: NOME COMUM | B4: NOME CIENTIFICO | C4: CONTAGEM | D4: DMCE (cm)
A5: Abiu | B5: Pouteria caimito (Ruiz & Pav.) Radlk. | C5: 1 | D5: 66.02254
A6: Abiurana | B6: Chrysophyllum prieurii A.DC. | C6: 1 | D6: 57.746483
A7: Amapá | B7: Parahancornia amapa (Huber ) Ducke | C7: 32 | D7: 50
A8: Amarelinho | B8: Euxylophora paraensis Huber | C8: 1 | D8: 61.247892
A9: Amescla | B9: Trattinnickia lawrencei Standl. ex Sw. | C9: 7 | D9: 57.746483
A10: Anani | B10: Symphonia globulifera L.f. | C10: 2 | D10: 64.112681
A11: Angelim-Pedra | B11: Hymenolobium petraeum Ducke | C11: 39 | D11: 51.380285
A12: Angelim-Vermelho | B12: Dinizia excelsa Ducke | C12: 2 | D12: 65.70423
A13: Araracanga | B13: Aspidosperma spruceanum Benth. ex Müll.Arg. | C13: 35 | D13: 51.380285
A14: Axixá | B14: Sterculia apeibophylla Ducke | C14: 19 | D14: 50
A15: Axuá | B15: Sacoglottis guianensis Benth. | C15: 14 | D15: 57.746483
A16: Barrote | B16: Tetragastris panamensis (Engl.) Kuntze | C16: 23 | D16: 54.563384
... A102: Virola | B102: Virola sebifera Aubl. | C102: 56 | D102: 50
A103: Total Geral | C103: 4936 | D103: 50

Sheet DISTRIBUICAO-ESPECIES
A1: N° UT | B1: 1 | C1: Título = | D1: =_xlfn.CONCAT(B2, " | UT",B1, " (DMCE = ",ROUND(D2,0),")") -> Cumaru | UT1 (DMCE = 80)
A2: NOME COMUM | B2: Cumaru | C2: DMCE = | D2: =VLOOKUP(B2,Lista_Especie,4,FALSE) -> 80
A4: Rótulos de Linha | B4: Contagem de NOME COMUM
A5: 30-40 | B5: 1
A6: 40-50 | B6: 3
A7: 50-60 | B7: 6
A8: 60-70 | B8: 5
A9: 70-80 | B9: 8
A10: 80-90 | B10: 3
A11: 90-100 | B11: 2
A12: 110-120 | B12: 1
A13: 130-140 | B13: 1
A14: Total Geral | B14: 30

Sheet MANUTENCAO
A1: N° UT | B1: 2
A2: COMERCIAIS | B2: Sim
A4: Contagem de NOME COMUM | B4: Rótulos de Coluna
A5: Rótulos de Linha | B5: Explorar | C5: Matriz | D5: Remanescente | E5: Total Geral | I5: AEEF | J5: Vulnerável | K5: 3/100ha | L5: 10% | M5: 4/100ha | N5: 15% | O5: Quantas Manter? | P5: Situação
A6: Angelim-Pedra | B6: 8 | C6: 9 | D6: 1 | E6: 18 | I6: =VLOOKUP($B$1,AEEF[],2,FALSE) -> 277.2759 | J6: =VLOOKUP(A6,ESPECIES[],4,FALSE) -> Não | K6: =IF(ROUNDUP((3*MANU[[#This Row],[AEEF]])/100,0)<3,"3",ROUNDUP((3*MANU[[#This Row],[AEEF]])/100,0)) -> 9 | L6: =ROUNDUP((B6+C6)*0.1,0) -> 2 | M6: =IF(ROUNDUP((4*MANU[[#This Row],[AEEF]])/100,0)<4,"4",ROUNDUP((4*MANU[[#This Row],[AEEF]])/100,0)) -> 12 | N6: =ROUNDUP((B6+C6)*0.15,0) -> 3 | O6: =IF(MANU[[#This Row],[Vulnerável]]="Não",MAX(MANU[[#This Row],[3/100ha]:[10%]]), MAX(MANU[[#This Row],[4/100ha]:[15%]])) -> 9 | P6: =IF(MANU[[#This Row],[Quantas Manter?]]<=C6, "CJ", "DL") -> CJ
A7: Cedrarana | B7: 38 | C7: 9 | D7: 2 | E7: 49 | I7: =VLOOKUP($B$1,AEEF[],2,FALSE) -> 277.2759 | J7: =VLOOKUP(A7,ESPECIES[],4,FALSE) -> Não | K7: =IF(ROUNDUP((3*MANU[[#This Row],[AEEF]])/100,0)<3,"3",ROUNDUP((3*MANU[[#This Row],[AEEF]])/100,0)) -> 9 | L7: =ROUNDUP((B7+C7)*0.1,0) -> 5 | M7: =IF(ROUNDUP((4*MANU[[#This Row],[AEEF]])/100,0)<4,"4",ROUNDUP((4*MANU[[#This Row],[AEEF]])/100,0)) -> 12 | N7: =ROUNDUP((B7+C7)*0.15,0) -> 8 | O7: =IF(MANU[[#This Row],[Vulnerável]]="Não",MAX(MANU[[#This Row],[3/100ha]:[10%]]), MAX(MANU[[#This Row],[4/100ha]:[15%]])) -> 9 | P7: =IF(MANU[[#This Row],[Quantas Manter?]]<=C7, "CJ", "DL") -> CJ
A8: Cumaru | C8: 1 | D8: 10 | E8: 11 | I8: =VLOOKUP($B$1,AEEF[],2,FALSE) -> 277.2759 | J8: =VLOOKUP(A8,ESPECIES[],4,FALSE) -> Vulneravel | K8: =IF(ROUNDUP((3*MANU[[#This Row],[AEEF]])/100,0)<3,"3",ROUNDUP((3*MANU[[#This Row],[AEEF]])/100,0)) -> 9 | L8: =ROUNDUP((B8+C8)*0.1,0) -> 1 | M8: =IF(ROUNDUP((4*MANU[[#This Row],[AEEF]])/100,0)<4,"4",ROUNDUP((4*MANU[[#This Row],[AEEF]])/100,0)) -> 12 | N8: =ROUNDUP((B8+C8)*0.15,0) -> 1 | O8: =IF(MANU[[#This Row],[Vulnerável]]="Não",MAX(MANU[[#This Row],[3/100ha]:[10%]]), MAX(MANU[[#This Row],[4/100ha]:[15%]])) -> 12 | P8: =IF(MANU[[#This Row],[Quantas Manter?]]<=C8, "CJ", "DL") -> DL
A9: Cupiúba | B9: 157 | C9: 18 | D9: 18 | E9: 193 | I9: =VLOOKUP($B$1,AEEF[],2,FALSE) -> 277.2759 | J9: =VLOOKUP(A9,ESPECIES[],4,FALSE) -> Não | K9: =IF(ROUNDUP((3*MANU[[#This Row],[AEEF]])/100,0)<3,"3",ROUNDUP((3*MANU[[#This Row],[AEEF]])/100,0)) -> 9 | L9: =ROUNDUP((B9+C9)*0.1,0) -> 18 | M9: =IF(ROUNDUP((4*MANU[[#This Row],[AEEF]])/100,0)<4,"4",ROUNDUP((4*MANU[[#This Row],[AEEF]])/100,0)) -> 12 | N9: =ROUNDUP((B9+C9)*0.15,0) -> 27 | O9: =IF(MANU[[#This Row],[Vulnerável]]="Não",MAX(MANU[[#This Row],[3/100ha]:[10%]]), MAX(MANU[[#This Row],[4/100ha]:[15%]])) -> 18 | P9: =IF(MANU[[#This Row],[Quantas Manter?]]<=C9, "CJ", "DL") -> CJ
A10: Freijó | C10: 3 | D10: 2 | E10: 5 | I10: =VLOOKUP($B$1,AEEF[],2,FALSE) -> 277.2759 | J10: =VLOOKUP(A10,ESPECIES[],4,FALSE) -> Não | K10: =IF(ROUNDUP((3*MANU[[#This Row],[AEEF]])/100,0)<3,"3",ROUNDUP((3*MANU[[#This Row],[AEEF]])/100,0)) -> 9 | L10: =ROUNDUP((B10+C10)*0.1,0) -> 1 | M10: =IF(ROUNDUP((4*MANU[[#This Row],[AEEF]])/100,0)<4,"4",ROUNDUP((4*MANU[[#This Row],[AEEF]])/100,0)) -> 12 | N10: =ROUNDUP((B10+C10)*0.15,0) -> 1 | O10: =IF(MANU[[#This Row],[Vulnerável]]="Não",MAX(MANU[[#This Row],[3/100ha]:[10%]]), MAX(MANU[[#This Row],[4/100ha]:[15%]])) -> 9 | P10: =IF(MANU[[#This Row],[Quantas Manter?]]<=C10, "CJ", "DL") -> DL
A11: Garapa | B11: 19 | C11: 9 | D11: 2 | E11: 30 | I11: =VLOOKUP($B$1,AEEF[],2,FALSE) -> 277.2759 | J11: =VLOOKUP(A11,ESPECIES[],4,FALSE) -> Não | K11: =IF(ROUNDUP((3*MANU[[#This Row],[AEEF]])/100,0)<3,"3",ROUNDUP((3*MANU[[#This Row],[AEEF]])/100,0)) -> 9 | L11: =ROUNDUP((B11+C11)*0.1,0) -> 3 | M11: =IF(ROUNDUP((4*MANU[[#This Row],[AEEF]])/100,0)<4,"4",ROUNDUP((4*MANU[[#This Row],[AEEF]])/100,0)) -> 12 | N11: =ROUNDUP((B11+C11)*0.15,0) -> 5 | O11: =IF(MANU[[#This Row],[Vulnerável]]="Não",MAX(MANU[[#This Row],[3/100ha]:[10%]]), MAX(MANU[[#This Row],[4/100ha]:[15%]])) -> 9 | P11: =IF(MANU[[#This Row],[Quantas Manter?]]<=C11, "CJ", "DL") -> CJ
A12: Jarana | B12: 36 | C12: 9 | D12: 6 | E12: 51 | I12: =VLOOKUP($B$1,AEEF[],2,FALSE) -> 277.2759 | J12: =VLOOKUP(A12,ESPECIES[],4,FALSE) -> Não | K12: =IF(ROUNDUP((3*MANU[[#This Row],[AEEF]])/100,0)<3,"3",ROUNDUP((3*MANU[[#This Row],[AEEF]])/100,0)) -> 9 | L12: =ROUNDUP((B12+C12)*0.1,0) -> 5 | M12: =IF(ROUNDUP((4*MANU[[#This Row],[AEEF]])/100,0)<4,"4",ROUNDUP((4*MANU[[#This Row],[AEEF]])/100,0)) -> 12 | N12: =ROUNDUP((B12+C12)*0.15,0) -> 7 | O12: =IF(MANU[[#This Row],[Vulnerável]]="Não",MAX(MANU[[#This Row],[3/100ha]:[10%]]), MAX(MANU[[#This Row],[4/100ha]:[15%]])) -> 9 | P12: =IF(MANU[[#This Row],[Quantas Manter?]]<=C12, "CJ", "DL") -> CJ
A13: Jatobá | B13: 11 | C13: 9 | D13: 2 | E13: 22 | I13: =VLOOKUP($B$1,AEEF[],2,FALSE) -> 277.2759 | J13: =VLOOKUP(A13,ESPECIES[],4,FALSE) -> Não | K13: =IF(ROUNDUP((3*MANU[[#This Row],[AEEF]])/100,0)<3,"3",ROUNDUP((3*MANU[[#This Row],[AEEF]])/100,0)) -> 9 | L13: =ROUNDUP((B13+C13)*0.1,0) -> 2 | M13: =IF(ROUNDUP((4*MANU[[#This Row],[AEEF]])/100,0)<4,"4",ROUNDUP((4*MANU[[#This Row],[AEEF]])/100,0)) -> 12 | N13: =ROUNDUP((B13+C13)*0.15,0) -> 3 | O13: =IF(MANU[[#This Row],[Vulnerável]]="Não",MAX(MANU[[#This Row],[3/100ha]:[10%]]), MAX(MANU[[#This Row],[4/100ha]:[15%]])) -> 9 | P13: =IF(MANU[[#This Row],[Quantas Manter?]]<=C13, "CJ", "DL") -> CJ
A14: Louro | B14: 27 | C14: 9 | D14: 10 | E14: 46 | I14: =VLOOKUP($B$1,AEEF[],2,FALSE) -> 277.2759 | J14: =VLOOKUP(A14,ESPECIES[],4,FALSE) -> Não | K14: =IF(ROUNDUP((3*MANU[[#This Row],[AEEF]])/100,0)<3,"3",ROUNDUP((3*MANU[[#This Row],[AEEF]])/100,0)) -> 9 | L14: =ROUNDUP((B14+C14)*0.1,0) -> 4 | M14: =IF(ROUNDUP((4*MANU[[#This Row],[AEEF]])/100,0)<4,"4",ROUNDUP((4*MANU[[#This Row],[AEEF]])/100,0)) -> 12 | N14: =ROUNDUP((B14+C14)*0.15,0) -> 6 | O14: =IF(MANU[[#This Row],[Vulnerável]]="Não",MAX(MANU[[#This Row],[3/100ha]:[10%]]), MAX(MANU[[#This Row],[4/100ha]:[15%]])) -> 9 | P14: =IF(MANU[[#This Row],[Quantas Manter?]]<=C14, "CJ", "DL") -> CJ
A15: Maçaranduba | B15: 21 | C15: 9 | D15: 7 | E15: 37 | I15: =VLOOKUP($B$1,AEEF[],2,FALSE) -> 277.2759 | J15: =VLOOKUP(A15,ESPECIES[],4,FALSE) -> Não | K15: =IF(ROUNDUP((3*MANU[[#This Row],[AEEF]])/100,0)<3,"3",ROUNDUP((3*MANU[[#This Row],[AEEF]])/100,0)) -> 9 | L15: =ROUNDUP((B15+C15)*0.1,0) -> 3 | M15: =IF(ROUNDUP((4*MANU[[#This Row],[AEEF]])/100,0)<4,"4",ROUNDUP((4*MANU[[#This Row],[AEEF]])/100,0)) -> 12 | N15: =ROUNDUP((B15+C15)*0.15,0) -> 5 | O15: =IF(MANU[[#This Row],[Vulnerável]]="Não",MAX(MANU[[#This Row],[3/100ha]:[10%]]), MAX(MANU[[#This Row],[4/100ha]:[15%]])) -> 9 | P15: =IF(MANU[[#This Row],[Quantas Manter?]]<=C15, "CJ", "DL") -> CJ
A16: Muiracatiara | B16: 37 | C16: 9 | D16: 10 | E16: 56 | I16: =VLOOKUP($B$1,AEEF[],2,FALSE) -> 277.2759 | J16: =VLOOKUP(A16,ESPECIES[],4,FALSE) -> Não | K16: =IF(ROUNDUP((3*MANU[[#This Row],[AEEF]])/100,0)<3,"3",ROUNDUP((3*MANU[[#This Row],[AEEF]])/100,0)) -> 9 | L16: =ROUNDUP((B16+C16)*0.1,0) -> 5 | M16: =IF(ROUNDUP((4*MANU[[#This Row],[AEEF]])/100,0)<4,"4",ROUNDUP((4*MANU[[#This Row],[AEEF]])/100,0)) -> 12 | N16: =ROUNDUP((B16+C16)*0.15,0) -> 7 | O16: =IF(MANU[[#This Row],[Vulnerável]]="Não",MAX(MANU[[#This Row],[3/100ha]:[10%]]), MAX(MANU[[#This Row],[4/100ha]:[15%]])) -> 9 | P16: =IF(MANU[[#This Row],[Quantas Manter?]]<=C16, "CJ", "DL") -> CJ
A17: Orelha-De-Macaco | B17: 33 | C17: 9 | D17: 1 | E17: 43 | I17: =VLOOKUP($B$1,AEEF[],2,FALSE) -> 277.2759 | J17: =VLOOKUP(A17,ESPECIES[],4,FALSE) -> Não | K17: =IF(ROUNDUP((3*MANU[[#This Row],[AEEF]])/100,0)<3,"3",ROUNDUP((3*MANU[[#This Row],[AEEF]])/100,0)) -> 9 | L17: =ROUNDUP((B17+C17)*0.1,0) -> 5 | M17: =IF(ROUNDUP((4*MANU[[#This Row],[AEEF]])/100,0)<4,"4",ROUNDUP((4*MANU[[#This Row],[AEEF]])/100,0)) -> 12 | N17: =ROUNDUP((B17+C17)*0.15,0) -> 7 | O17: =IF(MANU[[#This Row],[Vulnerável]]="Não",MAX(MANU[[#This Row],[3/100ha]:[10%]]), MAX(MANU[[#This Row],[4/100ha]:[15%]])) -> 9 | P17: =IF(MANU[[#This Row],[Quantas Manter?]]<=C17, "CJ", "DL") -> CJ
A18: Pequi | B18: 18 | C18: 9 | D18: 3 | E18: 30 | I18: =VLOOKUP($B$1,AEEF[],2,FALSE) -> 277.2759 | J18: =VLOOKUP(A18,ESPECIES[],4,FALSE) -> Não | K18: =IF(ROUNDUP((3*MANU[[#This Row],[AEEF]])/100,0)<3,"3",ROUNDUP((3*MANU[[#This Row],[AEEF]])/100,0)) -> 9 | L18: =ROUNDUP((B18+C18)*0.1,0) -> 3 | M18: =IF(ROUNDUP((4*MANU[[#This Row],[AEEF]])/100,0)<4,"4",ROUNDUP((4*MANU[[#This Row],[AEEF]])/100,0)) -> 12 | N18: =ROUNDUP((B18+C18)*0.15,0) -> 5 | O18: =IF(MANU[[#This Row],[Vulnerável]]="Não",MAX(MANU[[#This Row],[3/100ha]:[10%]]), MAX(MANU[[#This Row],[4/100ha]:[15%]])) -> 9 | P18: =IF(MANU[[#This Row],[Quantas Manter?]]<=C18, "CJ", "DL") -> CJ
A19: Quarubarana | B19: 63 | C19: 9 | D19: 2 | E19: 74 | I19: =VLOOKUP($B$1,AEEF[],2,FALSE) -> 277.2759 | J19: =VLOOKUP(A19,ESPECIES[],4,FALSE) -> Não | K19: =IF(ROUNDUP((3*MANU[[#This Row],[AEEF]])/100,0)<3,"3",ROUNDUP((3*MANU[[#This Row],[AEEF]])/100,0)) -> 9 | L19: =ROUNDUP((B19+C19)*0.1,0) -> 8 | M19: =IF(ROUNDUP((4*MANU[[#This Row],[AEEF]])/100,0)<4,"4",ROUNDUP((4*MANU[[#This Row],[AEEF]])/100,0)) -> 12 | N19: =ROUNDUP((B19+C19)*0.15,0) -> 11 | O19: =IF(MANU[[#This Row],[Vulnerável]]="Não",MAX(MANU[[#This Row],[3/100ha]:[10%]]), MAX(MANU[[#This Row],[4/100ha]:[15%]])) -> 9 | P19: =IF(MANU[[#This Row],[Quantas Manter?]]<=C19, "CJ", "DL") -> CJ
A20: Sapucaia | B20: 8 | C20: 9 | E20: 17 | I20: =VLOOKUP($B$1,AEEF[],2,FALSE) -> 277.2759 | J20: =VLOOKUP(A20,ESPECIES[],4,FALSE) -> Não | K20: =IF(ROUNDUP((3*MANU[[#This Row],[AEEF]])/100,0)<3,"3",ROUNDUP((3*MANU[[#This Row],[AEEF]])/100,0)) -> 9 | L20: =ROUNDUP((B20+C20)*0.1,0) -> 2 | M20: =IF(ROUNDUP((4*MANU[[#This Row],[AEEF]])/100,0)<4,"4",ROUNDUP((4*MANU[[#This Row],[AEEF]])/100,0)) -> 12 | N20: =ROUNDUP((B20+C20)*0.15,0) -> 3 | O20: =IF(MANU[[#This Row],[Vulnerável]]="Não",MAX(MANU[[#This Row],[3/100ha]:[10%]]), MAX(MANU[[#This Row],[4/100ha]:[15%]])) -> 9 | P20: =IF(MANU[[#This Row],[Quantas Manter?]]<=C20, "CJ", "DL") -> CJ
A21: Tamburi | B21: 22 | C21: 9 | D21: 1 | E21: 32 | I21: =VLOOKUP($B$1,AEEF[],2,FALSE) -> 277.2759 | J21: =VLOOKUP(A21,ESPECIES[],4,FALSE) -> Não | K21: =IF(ROUNDUP((3*MANU[[#This Row],[AEEF]])/100,0)<3,"3",ROUNDUP((3*MANU[[#This Row],[AEEF]])/100,0)) -> 9 | L21: =ROUNDUP((B21+C21)*0.1,0) -> 4 | M21: =IF(ROUNDUP((4*MANU[[#This Row],[AEEF]])/100,0)<4,"4",ROUNDUP((4*MANU[[#This Row],[AEEF]])/100,0)) -> 12 | N21: =ROUNDUP((B21+C21)*0.15,0) -> 5 | O21: =IF(MANU[[#This Row],[Vulnerável]]="Não",MAX(MANU[[#This Row],[3/100ha]:[10%]]), MAX(MANU[[#This Row],[4/100ha]:[15%]])) -> 9 | P21: =IF(MANU[[#This Row],[Quantas Manter?]]<=C21, "CJ", "DL") -> CJ
A22: Tauari | B22: 201 | C22: 23 | D22: 37 | E22: 261 | I22: =VLOOKUP($B$1,AEEF[],2,FALSE) -> 277.2759 | J22: =VLOOKUP(A22,ESPECIES[],4,FALSE) -> Não | K22: =IF(ROUNDUP((3*MANU[[#This Row],[AEEF]])/100,0)<3,"3",ROUNDUP((3*MANU[[#This Row],[AEEF]])/100,0)) -> 9 | L22: =ROUNDUP((B22+C22)*0.1,0) -> 23 | M22: =IF(ROUNDUP((4*MANU[[#This Row],[AEEF]])/100,0)<4,"4",ROUNDUP((4*MANU[[#This Row],[AEEF]])/100,0)) -> 12 | N22: =ROUNDUP((B22+C22)*0.15,0) -> 34 | O22: =IF(MANU[[#This Row],[Vulnerável]]="Não",MAX(MANU[[#This Row],[3/100ha]:[10%]]), MAX(MANU[[#This Row],[4/100ha]:[15%]])) -> 23 | P22: =IF(MANU[[#This Row],[Quantas Manter?]]<=C22, "CJ", "DL") -> CJ
A23: Taxi | B23: 243 | C23: 28 | D23: 11 | E23: 282 | I23: =VLOOKUP($B$1,AEEF[],2,FALSE) -> 277.2759 | J23: =VLOOKUP(A23,ESPECIES[],4,FALSE) -> Não | K23: =IF(ROUNDUP((3*MANU[[#This Row],[AEEF]])/100,0)<3,"3",ROUNDUP((3*MANU[[#This Row],[AEEF]])/100,0)) -> 9 | L23: =ROUNDUP((B23+C23)*0.1,0) -> 28 | M23: =IF(ROUNDUP((4*MANU[[#This Row],[AEEF]])/100,0)<4,"4",ROUNDUP((4*MANU[[#This Row],[AEEF]])/100,0)) -> 12 | N23: =ROUNDUP((B23+C23)*0.15,0) -> 41 | O23: =IF(MANU[[#This Row],[Vulnerável]]="Não",MAX(MANU[[#This Row],[3/100ha]:[10%]]), MAX(MANU[[#This Row],[4/100ha]:[15%]])) -> 28 | P23: =IF(MANU[[#This Row],[Quantas Manter?]]<=C23, "CJ", "DL") -> CJ
A24: Timborana | B24: 160 | C24: 18 | D24: 25 | E24: 203 | I24: =VLOOKUP($B$1,AEEF[],2,FALSE) -> 277.2759 | J24: =VLOOKUP(A24,ESPECIES[],4,FALSE) -> Não | K24: =IF(ROUNDUP((3*MANU[[#This Row],[AEEF]])/100,0)<3,"3",ROUNDUP((3*MANU[[#This Row],[AEEF]])/100,0)) -> 9 | L24: =ROUNDUP((B24+C24)*0.1,0) -> 18 | M24: =IF(ROUNDUP((4*MANU[[#This Row],[AEEF]])/100,0)<4,"4",ROUNDUP((4*MANU[[#This Row],[AEEF]])/100,0)) -> 12 | N24: =ROUNDUP((B24+C24)*0.15,0) -> 27 | O24: =IF(MANU[[#This Row],[Vulnerável]]="Não",MAX(MANU[[#This Row],[3/100ha]:[10%]]), MAX(MANU[[#This Row],[4/100ha]:[15%]])) -> 18 | P24: =IF(MANU[[#This Row],[Quantas Manter?]]<=C24, "CJ", "DL") -> CJ
A25: Total Geral | B25: 1102 | C25: 208 | D25: 150 | E25: 1460

Sheet EXPLORAR
A1: N° UT | B1: (Tudo)
A2: CATEGORIA | B2: Explorar
A4: NOME CIENTIFICO | B4: NOME COMUM | C4: INDIVÍDUOS | D4: v (m³/ha) | E4: v (m³)
A5: Apuleia leiocarpa (Vogel) J.F.Macbr. | B5: Garapa | C5: 90 | D5: 1.5371609 | E5: 878.55754
A6: Astronium lecointei Ducke | B6: Muiracatiara | C6: 134 | D6: 1.8541445 | E6: 1059.7281
A7: Caryocar villosum (Aubl.) Pers. | B7: Pequi | C7: 18 | D7: 0.420913 | E7: 240.57097
A8: Cedrelinga catenaeformis Ducke | B8: Cedrarana | C8: 70 | D8: 2.2961672 | E8: 1312.3643
A9: Cordia goeldiana Huber | B9: Freijó | C9: 4 | D9: 0.045754894 | E9: 26.151008
A10: Couratari guianensis Aubl. | B10: Tauari | C10: 420 | D10: 5.7303119 | E10: 3275.1346
A11: Enterolobium contortisiliquum (Vell.) Morong | B11: Tamburi | C11: 31 | D11: 0.7162553 | E11: 409.37256
A12: Erisma uncinatum Warm. | B12: Quarubarana | C12: 63 | D12: 1.5353397 | E12: 877.51667
A13: Goupia glabra Aubl. | B13: Cupiúba | C13: 157 | D13: 2.2769967 | E13: 1301.4075
A14: Hymenaea courbaril L. | B14: Jatobá | C14: 42 | D14: 0.74631095 | E14: 426.55074
A15: Hymenolobium petraeum Ducke | B15: Angelim-Pedra | C15: 19 | D15: 0.36986272 | E15: 211.39341
A16: Lecythis chartacea O.Berg | B16: Jarana | C16: 95 | D16: 1.2135958 | E16: 693.62534
... A22: Tachigali myrmecophila Ducke | B22: Taxi | C22: 481 | D22: 4.82149 | E22: 2755.7014
A23: Total Geral | C23: 2212 | D23: 29.994522 | E23: 17143.237

Sheet  MODELO-1-P
A1: N° UT | B1: (Tudo) | F1: N° UT | G1: (Tudo)
A2: COMERCIAIS | B2: (Tudo) | F2: COMERCIAIS | G2: (Tudo)
B4: Rótulos de Coluna | G4: Rótulos de Coluna | K4: Espécie | L4: DAP < DMCE | N4: DAP ≥ DMCE | P4: Total
A5: Rótulos de Linha | B5: DAP < DMCE | C5: DAP ≥ DMCE | D5: Total Geral | F5: Rótulos de Linha | G5: DAP < DMCE | H5: DAP ≥ DMCE | I5: Total Geral | L5: Subtotal | M5: % | N5: Subtotal | O5: %
A6: Abiu | F6: Abiu | K6: =A6 -> Abiu
A7: N | B7: 1 | D7: 1 | F7: N | G7: 1 | H7: 0 | I7: 1 | K7: =A7 -> N | L7: =B7 -> 1 | M7: =G7 -> 1 | N7: =C7 -> 0 | O7: =H7 -> 0 | P7: =D7 -> 1
A8: G | B8: 0.00043128523 | D8: 0.00043128523 | F8: G | G8: 1 | H8: 0 | I8: 1 | K8: =A8 -> G | L8: =B8 -> 0.00043128523 | M8: =G8 -> 1 | N8: =C8 -> 0 | O8: =H8 -> 0 | P8: =D8 -> 0.00043128523
A9: V | B9: 2.7607908 | D9: 2.7607908 | F9: V | G9: 1 | H9: 0 | I9: 1 | K9: =A9 -> V | L9: =B9 -> 2.7607908 | M9: =G9 -> 1 | N9: =C9 -> 0 | O9: =H9 -> 0 | P9: =D9 -> 2.7607908
A10: Abiurana | F10: Abiurana | K10: =A10 -> Abiurana
A11: N | B11: 1 | D11: 1 | F11: N | G11: 1 | H11: 0 | I11: 1 | K11: =A11 -> N | L11: =B11 -> 1 | M11: =G11 -> 1 | N11: =C11 -> 0 | O11: =H11 -> 0 | P11: =D11 -> 1
A12: G | B12: 0.00031327214 | D12: 0.00031327214 | F12: G | G12: 1 | H12: 0 | I12: 1 | K12: =A12 -> G | L12: =B12 -> 0.00031327214 | M12: =G12 -> 1 | N12: =C12 -> 0 | O12: =H12 -> 0 | P12: =D12 -> 0.00031327214
A13: V | B13: 2.1306868 | D13: 2.1306868 | F13: V | G13: 1 | H13: 0 | I13: 1 | K13: =A13 -> V | L13: =B13 -> 2.1306868 | M13: =G13 -> 1 | N13: =C13 -> 0 | O13: =H13 -> 0 | P13: =D13 -> 2.1306868
A14: Amapá | F14: Amapá | K14: =A14 -> Amapá
A15: N | B15: 6 | C15: 26 | D15: 32 | F15: N | G15: 0.1875 | H15: 0.8125 | I15: 1 | K15: =A15 -> N | L15: =B15 -> 6 | M15: =G15 -> 0.1875 | N15: =C15 -> 26 | O15: =H15 -> 0.8125 | P15: =D15 -> 32
A16: G | B16: 0.0015552639 | C16: 0.032576988 | D16: 0.034132252 | F16: G | G16: 0.045565815 | H16: 0.95443419 | I16: 1 | K16: =A16 -> G | L16: =B16 -> 0.0015552639 | M16: =G16 -> 0.045565815 | N16: =C16 -> 0.032576988 | O16: =H16 -> 0.95443419 | P16: =D16 -> 0.034132252
A17: V | B17: 8.3539578 | C17: 267.4762 | D17: 275.83016 | F17: V | G17: 0.0302866 | H17: 0.9697134 | I17: 1 | K17: =A17 -> V | L17: =B17 -> 8.3539578 | M17: =G17 -> 0.0302866 | N17: =C17 -> 267.4762 | O17: =H17 -> 0.9697134 | P17: =D17 -> 275.83016
A18: Amarelinho | F18: Amarelinho | K18: =A18 -> Amarelinho
A19: N | B19: 1 | D19: 1 | F19: N | G19: 1 | H19: 0 | I19: 1 | K19: =A19 -> N | L19: =B19 -> 1 | M19: =G19 -> 1 | N19: =C19 -> 0 | O19: =H19 -> 0 | P19: =D19 -> 1
A20: G | B20: 0.00036090342 | D20: 0.00036090342 | F20: G | G20: 1 | H20: 0 | I20: 1 | K20: =A20 -> G | L20: =B20 -> 0.00036090342 | M20: =G20 -> 1 | N20: =C20 -> 0 | O20: =H20 -> 0 | P20: =D20 -> 0.00036090342
A21: V | B21: 2.4546459 | D21: 2.4546459 | F21: V | G21: 1 | H21: 0 | I21: 1 | K21: =A21 -> V | L21: =B21 -> 2.4546459 | M21: =G21 -> 1 | N21: =C21 -> 0 | O21: =H21 -> 0 | P21: =D21 -> 2.4546459
A22: Amescla | F22: Amescla | K22: =A22 -> Amescla
A23: N | B23: 1 | C23: 6 | D23: 7 | F23: N | G23: 0.14285714 | H23: 0.85714286 | I23: 1 | K23: =A23 -> N | L23: =B23 -> 1 | M23: =G23 -> 0.14285714 | N23: =C23 -> 6 | O23: =H23 -> 0.85714286 | P23: =D23 -> 7
A24: G | B24: 0.00031327214 | C24: 0.0052878805 | D24: 0.0056011526 | F24: G | G24: 0.055929941 | H24: 0.94407006 | I24: 1 | K24: =A24 -> G | L24: =B24 -> 0.00031327214 | M24: =G24 -> 0.055929941 | N24: =C24 -> 0.0052878805 | O24: =H24 -> 0.94407006 | P24: =D24 -> 0.0056011526
A25: V | B25: 1.7546832 | C25: 40.510963 | D25: 42.265646 | F25: V | G25: 0.041515591 | H25: 0.95848441 | I25: 1 | K25: =A25 -> V | L25: =B25 -> 1.7546832 | M25: =G25 -> 0.041515591 | N25: =C25 -> 40.510963 | O25: =H25 -> 0.95848441 | P25: =D25 -> 42.265646
A26: Anani | F26: Anani | K26: =A26 -> Anani
A27: N | B27: 2 | D27: 2 | F27: N | G27: 1 | H27: 0 | I27: 1 | K27: =A27 -> N | L27: =B27 -> 2 | M27: =G27 -> 1 | N27: =C27 -> 0 | O27: =H27 -> 0 | P27: =D27 -> 2
A28: G | B28: 0.00090500839 | D28: 0.00090500839 | F28: G | G28: 1 | H28: 0 | I28: 1 | K28: =A28 -> G | L28: =B28 -> 0.00090500839 | M28: =G28 -> 1 | N28: =C28 -> 0 | O28: =H28 -> 0 | P28: =D28 -> 0.00090500839
A29: V | B29: 6.5173949 | D29: 6.5173949 | F29: V | G29: 1 | H29: 0 | I29: 1 | K29: =A29 -> V | L29: =B29 -> 6.5173949 | M29: =G29 -> 1 | N29: =C29 -> 0 | O29: =H29 -> 0 | P29: =D29 -> 6.5173949
A30: Angelim-Pedra | F30: Angelim-Pedra | K30: =A30 -> Angelim-Pedra
A31: N | B31: 2 | C31: 37 | D31: 39 | F31: N | G31: 0.051282051 | H31: 0.94871795 | I31: 1 | K31: =A31 -> N | L31: =B31 -> 2 | M31: =G31 -> 0.051282051 | N31: =C31 -> 37 | O31: =H31 -> 0.94871795 | P31: =D31 -> 39
A32: G | B32: 0.00047060436 | C32: 0.048534347 | D32: 0.049004951 | F32: G | G32: 0.0096032003 | H32: 0.9903968 | I32: 1 | K32: =A32 -> G | L32: =B32 -> 0.00047060436 | M32: =G32 -> 0.0096032003 | N32: =C32 -> 0.048534347 | O32: =H32 -> 0.9903968 | P32: =D32 -> 0.049004951
A33: V | B33: 2.3535037 | C33: 404.93997 | D33: 407.29348 | F33: V | G33: 0.0057783978 | H33: 0.9942216 | I33: 1 | K33: =A33 -> V | L33: =B33 -> 2.3535037 | M33: =G33 -> 0.0057783978 | N33: =C33 -> 404.93997 | O33: =H33 -> 0.9942216 | P33: =D33 -> 407.29348
A34: Angelim-Vermelho | F34: Angelim-Vermelho | K34: =A34 -> Angelim-Vermelho
A35: N | B35: 1 | C35: 1 | D35: 2 | F35: N | G35: 0.5 | H35: 0.5 | I35: 1 | K35: =A35 -> N | L35: =B35 -> 1 | M35: =G35 -> 0.5 | N35: =C35 -> 1 | O35: =H35 -> 0.5 | P35: =D35 -> 2
A36: G | B36: 0.00042639819 | C36: 0.0014079703 | D36: 0.0018343685 | F36: G | G36: 0.23244958 | H36: 0.76755042 | I36: 1 | K36: =A36 -> G | L36: =B36 -> 0.00042639819 | M36: =G36 -> 0.23244958 | N36: =C36 -> 0.0014079703 | O36: =H36 -> 0.76755042 | P36: =D36 -> 0.0018343685
A37: V | B37: 2.5589131 | C37: 11.266069 | D37: 13.824982 | F37: V | G37: 0.18509341 | H37: 0.81490659 | I37: 1 | K37: =A37 -> V | L37: =B37 -> 2.5589131 | M37: =G37 -> 0.18509341 | N37: =C37 -> 11.266069 | O37: =H37 -> 0.81490659 | P37: =D37 -> 13.824982
A38: Araracanga | F38: Araracanga | K38: =A38 -> Araracanga
A39: N | B39: 8 | C39: 27 | D39: 35 | F39: N | G39: 0.22857143 | H39: 0.77142857 | I39: 1 | K39: =A39 -> N | L39: =B39 -> 8 | M39: =G39 -> 0.22857143 | N39: =C39 -> 27 | O39: =H39 -> 0.77142857 | P39: =D39 -> 35
A40: G | B40: 0.0024199228 | C40: 0.019154948 | D40: 0.021574871 | F40: G | G40: 0.11216395 | H40: 0.88783605 | I40: 1 | K40: =A40 -> G | L40: =B40 -> 0.0024199228 | M40: =G40 -> 0.11216395 | N40: =C40 -> 0.019154948 | O40: =H40 -> 0.88783605 | P40: =D40 -> 0.021574871
A41: V | B41: 16.144245 | C41: 148.33113 | D41: 164.47538 | F41: V | G41: 0.098155995 | H41: 0.901844 | I41: 1 | K41: =A41 -> V | L41: =B41 -> 16.144245 | M41: =G41 -> 0.098155995 | N41: =C41 -> 148.33113 | O41: =H41 -> 0.901844 | P41: =D41 -> 164.47538
...

Sheet  MODELO-2-P 
A1: N° UT | B1: (Tudo) | I1: N° UT | J1: (Tudo)
A2: COMERCIAIS | B2: (Tudo) | I2: COMERCIAIS | J2: (Tudo)
B4: Rótulos de Coluna | J4: Rótulos de Coluna | Q4: Espécie | R4: DMCE | S4: Explorar | U4: Matriz | W4: Protegida | Y4: Remanescente | AA4: Remanescente 2 | AC4: Total | AD4: Total/ha
A5: Rótulos de Linha | B5: Explorar | C5: Matriz | D5: Protegida | E5: Remanescente | F5: Remanescente 2 | G5: Total Geral | I5: Rótulos de Linha | J5: Explorar | K5: Matriz | L5: Protegida | M5: Remanescente | N5: Remanescente 2 | O5: Total Geral | S5: Subtotal | T5: % | U5: Subtotal | V5: % | W5: Subtotal | X5: % | Y5: Subtotal | Z5: % | AA5: Subtotal | AB5: %
A6: Abiu | I6: Abiu | Q6: =A6 -> Abiu | R6: =IFERROR(VLOOKUP(Q6,'LISTA-ESPECIES'!$A$4:$D$102,4,FALSE),"") -> 66.02254
A7: N | E7: 1 | G7: 1 | I7: N | J7: 0 | K7: 0 | L7: 0 | M7: 1 | N7: 0 | O7: 1 | Q7: =A7 -> N | R7: =IFERROR(VLOOKUP(Q7,'LISTA-ESPECIES'!$A$4:$D$102,4,FALSE),"") | S7: =B7 -> 0 | T7: =J7 -> 0 | U7: =C7 -> 0 | V7: =K7 -> 0 | W7: =D7 -> 0 | X7: =L7 -> 0 | Y7: =E7 -> 1 | Z7: =M7 -> 1 | AA7: =F7 -> 0 | AB7: =N7 -> 0 | AC7: =G7 -> 1 | AD7: =AC7/SUM(AEEF[AEEF-UT]) -> 0.0017496417
A8: G | E8: 0.00043128523 | G8: 0.00043128523 | I8: G | J8: 0 | K8: 0 | L8: 0 | M8: 1 | N8: 0 | O8: 1 | Q8: =A8 -> G | R8: =IFERROR(VLOOKUP(Q8,'LISTA-ESPECIES'!$A$4:$D$102,4,FALSE),"") | S8: =B8 -> 0 | T8: =J8 -> 0 | U8: =C8 -> 0 | V8: =K8 -> 0 | W8: =D8 -> 0 | X8: =L8 -> 0 | Y8: =E8 -> 0.00043128523 | Z8: =M8 -> 1 | AA8: =F8 -> 0 | AB8: =N8 -> 0 | AC8: =G8 -> 0.00043128523 | AD8: =AC8/SUM(AEEF[AEEF-UT]) -> 7.5459461e-07
A9: V | E9: 2.7607908 | G9: 2.7607908 | I9: V | J9: 0 | K9: 0 | L9: 0 | M9: 1 | N9: 0 | O9: 1 | Q9: =A9 -> V | R9: =IFERROR(VLOOKUP(Q9,'LISTA-ESPECIES'!$A$4:$D$102,4,FALSE),"") | S9: =B9 -> 0 | T9: =J9 -> 0 | U9: =C9 -> 0 | V9: =K9 -> 0 | W9: =D9 -> 0 | X9: =L9 -> 0 | Y9: =E9 -> 2.7607908 | Z9: =M9 -> 1 | AA9: =F9 -> 0 | AB9: =N9 -> 0 | AC9: =G9 -> 2.7607908 | AD9: =AC9/SUM(AEEF[AEEF-UT]) -> 0.0048303946
A10: Abiurana | I10: Abiurana | Q10: =A10 -> Abiurana | R10: =IFERROR(VLOOKUP(Q10,'LISTA-ESPECIES'!$A$4:$D$102,4,FALSE),"") -> 57.746483
A11: N | E11: 1 | G11: 1 | I11: N | J11: 0 | K11: 0 | L11: 0 | M11: 1 | N11: 0 | O11: 1 | Q11: =A11 -> N | R11: =IFERROR(VLOOKUP(Q11,'LISTA-ESPECIES'!$A$4:$D$102,4,FALSE),"") | S11: =B11 -> 0 | T11: =J11 -> 0 | U11: =C11 -> 0 | V11: =K11 -> 0 | W11: =D11 -> 0 | X11: =L11 -> 0 | Y11: =E11 -> 1 | Z11: =M11 -> 1 | AA11: =F11 -> 0 | AB11: =N11 -> 0 | AC11: =G11 -> 1 | AD11: =AC11/SUM(AEEF[AEEF-UT]) -> 0.0017496417
A12: G | E12: 0.00031327214 | G12: 0.00031327214 | I12: G | J12: 0 | K12: 0 | L12: 0 | M12: 1 | N12: 0 | O12: 1 | Q12: =A12 -> G | R12: =IFERROR(VLOOKUP(Q12,'LISTA-ESPECIES'!$A$4:$D$102,4,FALSE),"") | S12: =B12 -> 0 | T12: =J12 -> 0 | U12: =C12 -> 0 | V12: =K12 -> 0 | W12: =D12 -> 0 | X12: =L12 -> 0 | Y12: =E12 -> 0.00031327214 | Z12: =M12 -> 1 | AA12: =F12 -> 0 | AB12: =N12 -> 0 | AC12: =G12 -> 0.00031327214 | AD12: =AC12/SUM(AEEF[AEEF-UT]) -> 5.4811398e-07
A13: V | E13: 2.1306868 | G13: 2.1306868 | I13: V | J13: 0 | K13: 0 | L13: 0 | M13: 1 | N13: 0 | O13: 1 | Q13: =A13 -> V | R13: =IFERROR(VLOOKUP(Q13,'LISTA-ESPECIES'!$A$4:$D$102,4,FALSE),"") | S13: =B13 -> 0 | T13: =J13 -> 0 | U13: =C13 -> 0 | V13: =K13 -> 0 | W13: =D13 -> 0 | X13: =L13 -> 0 | Y13: =E13 -> 2.1306868 | Z13: =M13 -> 1 | AA13: =F13 -> 0 | AB13: =N13 -> 0 | AC13: =G13 -> 2.1306868 | AD13: =AC13/SUM(AEEF[AEEF-UT]) -> 0.0037279384
A14: Amapá | I14: Amapá | Q14: =A14 -> Amapá | R14: =IFERROR(VLOOKUP(Q14,'LISTA-ESPECIES'!$A$4:$D$102,4,FALSE),"") -> 50
A15: N | C15: 26 | E15: 6 | G15: 32 | I15: N | J15: 0 | K15: 0.8125 | L15: 0 | M15: 0.1875 | N15: 0 | O15: 1 | Q15: =A15 -> N | R15: =IFERROR(VLOOKUP(Q15,'LISTA-ESPECIES'!$A$4:$D$102,4,FALSE),"") | S15: =B15 -> 0 | T15: =J15 -> 0 | U15: =C15 -> 26 | V15: =K15 -> 0.8125 | W15: =D15 -> 0 | X15: =L15 -> 0 | Y15: =E15 -> 6 | Z15: =M15 -> 0.1875 | AA15: =F15 -> 0 | AB15: =N15 -> 0 | AC15: =G15 -> 32 | AD15: =AC15/SUM(AEEF[AEEF-UT]) -> 0.055988534
A16: G | C16: 0.032576988 | E16: 0.0015552639 | G16: 0.034132252 | I16: G | J16: 0 | K16: 0.95443419 | L16: 0 | M16: 0.045565815 | N16: 0 | O16: 1 | Q16: =A16 -> G | R16: =IFERROR(VLOOKUP(Q16,'LISTA-ESPECIES'!$A$4:$D$102,4,FALSE),"") | S16: =B16 -> 0 | T16: =J16 -> 0 | U16: =C16 -> 0.032576988 | V16: =K16 -> 0.95443419 | W16: =D16 -> 0 | X16: =L16 -> 0 | Y16: =E16 -> 0.0015552639 | Z16: =M16 -> 0.045565815 | AA16: =F16 -> 0 | AB16: =N16 -> 0 | AC16: =G16 -> 0.034132252 | AD16: =AC16/SUM(AEEF[AEEF-UT]) -> 5.9719211e-05
A17: V | C17: 267.4762 | E17: 8.3539578 | G17: 275.83016 | I17: V | J17: 0 | K17: 0.9697134 | L17: 0 | M17: 0.0302866 | N17: 0 | O17: 1 | Q17: =A17 -> V | R17: =IFERROR(VLOOKUP(Q17,'LISTA-ESPECIES'!$A$4:$D$102,4,FALSE),"") | S17: =B17 -> 0 | T17: =J17 -> 0 | U17: =C17 -> 267.4762 | V17: =K17 -> 0.9697134 | W17: =D17 -> 0 | X17: =L17 -> 0 | Y17: =E17 -> 8.3539578 | Z17: =M17 -> 0.0302866 | AA17: =F17 -> 0 | AB17: =N17 -> 0 | AC17: =G17 -> 275.83016 | AD17: =AC17/SUM(AEEF[AEEF-UT]) -> 0.48260395
